<sdf version='1.7'>
  <model name='rmp_401'>
    <link name='base_footprint'>
      <inertial>
        <pose>0 0 0.1575 0 -0 0</pose>
        <mass>20</mass>
        <inertia>
          <ixx>0.741402</ixx>
          <ixy>0</ixy>
          <ixz>0</ixz>
          <iyy>0.3804</iyy>
          <iyz>1.70726e-16</iyz>
          <izz>0.983082</izz>
        </inertia>
      </inertial>
      <collision name='base_footprint_fixed_joint_lump__base_link_collision'>
        <pose>0 0 0.1575 0 -0 0</pose>
        <geometry>
          <box>
            <size>0.432 0.635 0.204</size>
          </box>
        </geometry>
        <surface>
          <contact>
            <ode/>
          </contact>
          <friction>
            <ode/>
          </friction>
        </surface>
      </collision>
      <visual name='base_footprint_fixed_joint_lump__base_link_visual'>
        <pose>-0.355 -0.345 -0.0425 1.5708 -0 0</pose>
        <geometry>
          <mesh>
            <scale>0.001 0.001 0.001</scale>
            <uri>/home/luckierdodge/dev_ws/install/mcity_proxy/share/mcity_proxy/meshes/chassis.stl</uri>
          </mesh>
        </geometry>
        <material>
          <script>
            <name>Gazebo/Red</name>
            <uri>file://media/materials/scripts/gazebo.material</uri>
          </script>
        </material>
      </visual>
      <visual name='base_footprint_fixed_joint_lump__gps_link_visual_1'>
        <pose>-0.01 -0.117 0.2375 0 -0 0</pose>
        <geometry>
          <box>
            <size>0.042 0.05 0.001</size>
          </box>
        </geometry>
        <material>
          <script>
            <name>Gazebo/Blue</name>
            <uri>file://media/materials/scripts/gazebo.material</uri>
          </script>
        </material>
      </visual>
    </link>
    <joint name='backwhl_l_joint' type='revolute'>
      <pose relative_to='base_footprint'>-0.24 -0.235 0.0675 0 0 -3.14159</pose>
      <parent>base_footprint</parent>
      <child>backwhl_l_link</child>
      <axis>
        <xyz>1 0 0</xyz>
        <limit>
          <lower>-1e+16</lower>
          <upper>1e+16</upper>
        </limit>
        <dynamics>
          <spring_reference>0</spring_reference>
          <spring_stiffness>0</spring_stiffness>
        </dynamics>
      </axis>
    </joint>
    <link name='backwhl_l_link'>
      <pose relative_to='backwhl_l_joint'>0 0 0 0 -0 0</pose>
      <inertial>
        <pose>0.029 0 0 0 1.5708 0</pose>
        <mass>1</mass>
        <inertia>
          <ixx>0.00349115</ixx>
          <ixy>0</ixy>
          <ixz>0</ixz>
          <iyy>0.00349115</iyy>
          <iyz>0</iyz>
          <izz>0.00577812</izz>
        </inertia>
      </inertial>
      <collision name='backwhl_l_link_collision'>
        <pose>0.029 0 0 0 1.5708 0</pose>
        <geometry>
          <cylinder>
            <length>0.085</length>
            <radius>0.1075</radius>
          </cylinder>
        </geometry>
        <surface>
          <contact>
            <ode/>
          </contact>
          <friction>
            <ode/>
          </friction>
        </surface>
      </collision>
      <visual name='backwhl_l_link_visual'>
        <pose>-0.595 -0.11 -0.11 1.5708 -0 0</pose>
        <geometry>
          <mesh>
            <scale>0.001 0.001 0.001</scale>
            <uri>/home/luckierdodge/dev_ws/install/mcity_proxy/share/mcity_proxy/meshes/back_wheel.stl</uri>
          </mesh>
        </geometry>
        <material>
          <script>
            <name>Gazebo/White</name>
            <uri>file://media/materials/scripts/gazebo.material</uri>
          </script>
        </material>
      </visual>
    </link>
    <joint name='backwhl_r_joint' type='revolute'>
      <pose relative_to='base_footprint'>0.24 -0.235 0.0675 0 -0 0</pose>
      <parent>base_footprint</parent>
      <child>backwhl_r_link</child>
      <axis>
        <xyz>1 0 0</xyz>
        <limit>
          <lower>-1e+16</lower>
          <upper>1e+16</upper>
        </limit>
        <dynamics>
          <spring_reference>0</spring_reference>
          <spring_stiffness>0</spring_stiffness>
        </dynamics>
      </axis>
    </joint>
    <link name='backwhl_r_link'>
      <pose relative_to='backwhl_r_joint'>0 0 0 0 -0 0</pose>
      <inertial>
        <pose>0.029 0 0 0 1.5708 0</pose>
        <mass>1</mass>
        <inertia>
          <ixx>0.00349115</ixx>
          <ixy>0</ixy>
          <ixz>0</ixz>
          <iyy>0.00349115</iyy>
          <iyz>0</iyz>
          <izz>0.00577812</izz>
        </inertia>
      </inertial>
      <collision name='backwhl_r_link_collision'>
        <pose>0.029 0 0 0 1.5708 0</pose>
        <geometry>
          <cylinder>
            <length>0.085</length>
            <radius>0.1075</radius>
          </cylinder>
        </geometry>
        <surface>
          <contact>
            <ode/>
          </contact>
          <friction>
            <ode/>
          </friction>
        </surface>
      </collision>
      <visual name='backwhl_r_link_visual'>
        <pose>-0.595 -0.11 -0.11 1.5708 -0 0</pose>
        <geometry>
          <mesh>
            <scale>0.001 0.001 0.001</scale>
            <uri>/home/luckierdodge/dev_ws/install/mcity_proxy/share/mcity_proxy/meshes/back_wheel.stl</uri>
          </mesh>
        </geometry>
        <material>
          <script>
            <name>Gazebo/White</name>
            <uri>file://media/materials/scripts/gazebo.material</uri>
          </script>
        </material>
      </visual>
    </link>
    <joint name='steer_joint' type='revolute'>
      <pose relative_to='base_footprint'>0 0.22 0.1575 0 -0 0</pose>
      <parent>base_footprint</parent>
      <child>front_steer_link</child>
      <axis>
        <xyz>0 0 1</xyz>
        <limit>
          <lower>-0.36</lower>
          <upper>0.36</upper>
          <effort>30</effort>
          <velocity>5</velocity>
        </limit>
        <dynamics>
          <spring_reference>0</spring_reference>
          <spring_stiffness>0</spring_stiffness>
        </dynamics>
      </axis>
    </joint>
    <link name='front_steer_link'>
      <pose relative_to='steer_joint'>0 0 0 0 -0 0</pose>
      <inertial>
        <pose>0 0 0 0 -0 0</pose>
        <mass>5</mass>
        <inertia>
          <ixx>0.0200417</ixx>
          <ixy>0</ixy>
          <ixz>0</ixz>
          <iyy>0.0915417</iyy>
          <iyz>0</iyz>
          <izz>0.104833</izz>
        </inertia>
      </inertial>
      <visual name='front_steer_link_visual'>
        <pose>-0.355 -0.565 -0.2 1.5708 -0 0</pose>
        <geometry>
          <mesh>
            <scale>0.001 0.001 0.001</scale>
            <uri>/home/luckierdodge/dev_ws/install/mcity_proxy/share/mcity_proxy/meshes/steering_arm.stl</uri>
          </mesh>
        </geometry>
        <material>
          <script>
            <name>Gazebo/Green</name>
            <uri>file://media/materials/scripts/gazebo.material</uri>
          </script>
        </material>
      </visual>
    </link>
    <joint name='frontwhl_l_joint' type='revolute'>
      <pose relative_to='front_steer_link'>-0.22 0 -0.09 0 0 -3.14159</pose>
      <parent>front_steer_link</parent>
      <child>frontwhl_l_link</child>
      <axis>
        <xyz>1 0 0</xyz>
        <limit>
          <lower>-1e+16</lower>
          <upper>1e+16</upper>
        </limit>
        <dynamics>
          <spring_reference>0</spring_reference>
          <spring_stiffness>0</spring_stiffness>
        </dynamics>
      </axis>
    </joint>
    <link name='frontwhl_l_link'>
      <pose relative_to='frontwhl_l_joint'>0 0 0 0 -0 0</pose>
      <inertial>
        <pose>0.048 0 0 0 1.5708 0</pose>
        <mass>1</mass>
        <inertia>
          <ixx>0.00349115</ixx>
          <ixy>0</ixy>
          <ixz>0</ixz>
          <iyy>0.00349115</iyy>
          <iyz>0</iyz>
          <izz>0.00577812</izz>
        </inertia>
      </inertial>
      <collision name='frontwhl_l_link_collision'>
        <pose>0.048 0 0 0 1.5708 0</pose>
        <geometry>
          <cylinder>
            <length>0.085</length>
            <radius>0.1075</radius>
          </cylinder>
        </geometry>
        <surface>
          <contact>
            <ode/>
          </contact>
          <friction>
            <ode/>
          </friction>
        </surface>
      </collision>
      <visual name='frontwhl_l_link_visual'>
        <pose>-0.575 -0.565 -0.11 1.5708 -0 0</pose>
        <geometry>
          <mesh>
            <scale>0.001 0.001 0.001</scale>
            <uri>/home/luckierdodge/dev_ws/install/mcity_proxy/share/mcity_proxy/meshes/front_wheel.stl</uri>
          </mesh>
        </geometry>
        <material>
          <script>
            <name>Gazebo/White</name>
            <uri>file://media/materials/scripts/gazebo.material</uri>
          </script>
        </material>
      </visual>
    </link>
    <joint name='frontwhl_r_joint' type='revolute'>
      <pose relative_to='front_steer_link'>0.22 0 -0.09 0 -0 0</pose>
      <parent>front_steer_link</parent>
      <child>frontwhl_r_link</child>
      <axis>
        <xyz>1 0 0</xyz>
        <limit>
          <lower>-1e+16</lower>
          <upper>1e+16</upper>
        </limit>
        <dynamics>
          <spring_reference>0</spring_reference>
          <spring_stiffness>0</spring_stiffness>
        </dynamics>
      </axis>
    </joint>
    <link name='frontwhl_r_link'>
      <pose relative_to='frontwhl_r_joint'>0 0 0 0 -0 0</pose>
      <inertial>
        <pose>0.048 0 0 0 1.5708 0</pose>
        <mass>1</mass>
        <inertia>
          <ixx>0.00349115</ixx>
          <ixy>0</ixy>
          <ixz>0</ixz>
          <iyy>0.00349115</iyy>
          <iyz>0</iyz>
          <izz>0.00577812</izz>
        </inertia>
      </inertial>
      <collision name='frontwhl_r_link_collision'>
        <pose>0.048 0 0 0 1.5708 0</pose>
        <geometry>
          <cylinder>
            <length>0.085</length>
            <radius>0.1075</radius>
          </cylinder>
        </geometry>
        <surface>
          <contact>
            <ode/>
          </contact>
          <friction>
            <ode/>
          </friction>
        </surface>
      </collision>
      <visual name='frontwhl_r_link_visual'>
        <pose>-0.575 -0.565 -0.11 1.5708 -0 0</pose>
        <geometry>
          <mesh>
            <scale>0.001 0.001 0.001</scale>
            <uri>/home/luckierdodge/dev_ws/install/mcity_proxy/share/mcity_proxy/meshes/front_wheel.stl</uri>
          </mesh>
        </geometry>
        <material>
          <script>
            <name>Gazebo/White</name>
            <uri>file://media/materials/scripts/gazebo.material</uri>
          </script>
        </material>
      </visual>
    </link>
  </model>
</sdf>
