<?xml version="1.0" ?>
<robot name="rmp_401" xmlns:xacro="http://ros.org/wiki/xacro">
  <!-- ****************** ROBOT CONSTANTS *******************************  -->
  <!-- Define the size of the robot's main chassis in meters -->
  <xacro:property name="base_width" value=".432"/>
  <xacro:property name="base_length" value=".635"/>
  <xacro:property name="base_height" value=".204"/>
  <!-- Define the shape of the robot's two back wheels in meters -->
  <xacro:property name="wheel_radius" value="0.1075"/>
  <xacro:property name="wheel_width" value="0.085"/>

  <!-- x-axis points forward, y-axis points to left, z-axis points upwards -->
  <!-- Define the gap between the wheel and chassis along y-axis in meters -->
  <xacro:property name="wheel_ygap" value="0.035"/>

  <!-- Position the wheels along the z-axis -->
  <xacro:property name="wheel_zoff" value="0.05"/>

  <!-- Position the wheels along the x-axis -->
  <xacro:property name="wheel_xoff" value="0.221"/>

  <!-- Position the caster wheel along the x-axis -->
  <xacro:property name="caster_xoff" value="0.217"/>

  <!-- Define intertial property macros  -->
  <xacro:macro name="box_inertia" params="m w h d">
    <inertial>
      <origin xyz="0 0 0" rpy="${pi/2} 0 ${pi/2}"/>
      <mass value="${m}"/>
      <inertia ixx="${(m/12) * (h*h + d*d)}" ixy="0.0" ixz="0.0" iyy="${(m/12) * (w*w + d*d)}" iyz="0.0" izz="${(m/12) * (w*w + h*h)}"/>
    </inertial>
  </xacro:macro>

  <xacro:macro name="cylinder_inertia" params="m r h">
    <inertial>
      <origin xyz="0 0 0" rpy="${pi/2} 0 0" />
      <mass value="${m}"/>
      <inertia ixx="${(m/12) * (3*r*r + h*h)}" ixy = "0" ixz = "0" iyy="${(m/12) * (3*r*r + h*h)}" iyz = "0" izz="${(m/2) * (r*r)}"/>
    </inertial>
  </xacro:macro>

  <xacro:macro name="sphere_inertia" params="m r">
    <inertial>
      <mass value="${m}"/>
      <inertia ixx="${(2/5) * m * (r*r)}" ixy="0.0" ixz="0.0" iyy="${(2/5) * m * (r*r)}" iyz="0.0" izz="${(2/5) * m * (r*r)}"/>
    </inertial>
  </xacro:macro>
  <!-- ****************** ROBOT BASE FOOTPRINT ***************************  -->
  <!-- Define the center of the main robot chassis projected on the ground -->
  <link name="base_footprint"/>

  <!-- The base footprint of the robot is located underneath the chassis -->
  <joint name="base_joint" type="fixed">
    <parent link="base_footprint"/>
    <child link="base_link" />
    <origin xyz="0.0 0.0 ${(wheel_radius+wheel_zoff)}" rpy="0 0 0"/>
  </joint>

  <!-- ********************** ROBOT BASE *********************************  -->
  <link name="base_link">
    <visual>
      <origin xyz="-.355 -.3450 -.200" rpy="1.5707963267949 0 0"/>
      <geometry>
        <mesh filename="package://mcity_proxy/meshes/chassis.stl" scale="0.001 0.001 0.001"/>
      </geometry>
      <material name="Red">
        <color rgba="${255/255} ${0/255} ${0/255} 1.0"/>
      </material>
    </visual>

    <collision>
      <geometry>
        <box size="${base_length} ${base_width} ${base_height}"/>
      </geometry>
    </collision>

    <xacro:box_inertia m="40.0" w="${base_width}" d="${base_length}" h="${base_height}"/>

  </link>

  <gazebo reference="base_link">
    <material>Gazebo/Red</material>
  </gazebo>

  <!-- ********************** STEER ARM  *********************************  -->
  <link name="front_steer_link">
    <visual>
      <origin xyz="-.355 -.5650 -.200" rpy="1.5707963267949 0 0"/>
      <geometry>
        <mesh filename="package://mcity_proxy/meshes/steering_arm.stl" scale="0.001 0.001 0.001"/>
      </geometry>
      <material name="Green">
        <color rgba="${0/255} ${255/255} ${0/255} 1.0"/>
      </material>
    </visual>

    <!-- <collision>
      <geometry>
        <box size="${base_length} ${base_width} ${base_height}"/>
      </geometry>
    </collision> -->

    <!-- <xacro:box_inertia m="40.0" w="${base_width}" d="${base_length}" h="${base_height}"/> -->

  </link>
  <joint name="steer_joint" type="revolute">
    <parent link="base_link"/>
    <child link="front_steer_link"/>
    <origin xyz="0 0.22 0" rpy="0 0 0"/>
    <limit upper="0.36" lower="-0.36" effort="30" velocity="5.0"/>
    <axis xyz="0 0 1"/>
  </joint>

  <gazebo reference="front_steer_link">
    <material>Gazebo/Green</material>
  </gazebo>

  <!-- *********************** FRONT WHEELS ******************************  -->

  <xacro:macro name="front_wheel" params="prefix x_offset offset_multiplier z_rotate">
    <link name="${prefix}_link">
      <visual>
        <origin xyz="${-.355 - offset_multiplier * x_offset} -.5650 -.110" rpy="1.5707963267949 0 0"/>
        <geometry>
          <mesh filename="package://mcity_proxy/meshes/front_wheel.stl" scale="0.001 0.001 0.001"/>
        </geometry>
        <material name="White">
          <color rgba="${255/255} ${255/255} ${255/255} 1.0"/>
        </material>
      </visual>

      <collision>
        <origin xyz="0 0 0" rpy="${pi/2} 0 0"/>
        <geometry>
          <cylinder radius="${wheel_radius}" length="${wheel_width}"/>
        </geometry>
      </collision>

      <xacro:cylinder_inertia m="110.5" r="${wheel_radius}" h="${wheel_width}"/>

    </link>

    <joint name="${prefix}_joint" type="continuous">
      <parent link="front_steer_link"/>
      <child link="${prefix}_link"/>
      <!-- <origin xyz="${x_reflect*wheel_xoff} ${y_reflect*(base_width/2+wheel_ygap)} ${-wheel_zoff}" rpy="0 0 0"/> -->
      <origin xyz="${x_offset} 0 -.09" rpy="0 0 ${z_rotate}"/>
      <!-- <limit upper="3.1415" lower="-3.1415" effort="30" velocity="5.0"/> -->
      <axis xyz="1 0 0"/>
    </joint>
  </xacro:macro>

  <xacro:front_wheel prefix="frontwhl_r" x_offset=".22" offset_multiplier="1" z_rotate="0"/>
  <xacro:front_wheel prefix="frontwhl_l" x_offset="-.22" offset_multiplier="-1" z_rotate="3.14159265359"/>

  <!-- ***********************  BACK WHEELS ******************************  -->

  <xacro:macro name="back_wheel" params="prefix x_offset offset_multiplier z_rotate">
    <link name="${prefix}_link">
      <visual>
        <origin xyz="${-.355 - offset_multiplier * x_offset} -.1100 -.110" rpy="1.5707963267949 0 0"/>
        <geometry>
          <mesh filename="package://mcity_proxy/meshes/back_wheel.stl" scale="0.001 0.001 0.001"/>
        </geometry>
        <material name="White">
          <color rgba="${255/255} ${255/255} ${255/255} 1.0"/>
        </material>
      </visual>

      <collision>
        <origin xyz="0 0 0" rpy="${pi/2} 0 0"/>
        <geometry>
          <cylinder radius="${wheel_radius}" length="${wheel_width}"/>
        </geometry>
      </collision>

      <xacro:cylinder_inertia m="110.5" r="${wheel_radius}" h="${wheel_width}"/>

    </link>

    <joint name="${prefix}_joint" type="continuous">
      <parent link="base_link"/>
      <child link="${prefix}_link"/>
      <!-- <origin xyz="${x_reflect*wheel_xoff} ${y_reflect*(base_width/2+wheel_ygap)} ${-wheel_zoff}" rpy="0 0 0"/> -->
      <origin xyz="${x_offset} -.235 -.09" rpy="0 0 ${z_rotate}"/>
      <!-- <limit upper="3.1415" lower="-3.1415" effort="30" velocity="5.0"/> -->
      <axis xyz="1 0 0"/>
    </joint>
  </xacro:macro>

  <xacro:back_wheel prefix="backwhl_r" x_offset=".24" offset_multiplier="1" z_rotate="0"/>
  <xacro:back_wheel prefix="backwhl_l" x_offset="-.24" offset_multiplier="-1" z_rotate="3.14159265359"/>

  <!-- *********************** GPS SETUP **********************************  -->
  <link name="gps_link">
    <visual>
      <geometry>
        <box size=".042 .05 .001"/>
      </geometry>
      <material name="Blue">
        <color rgba="${0/255} ${0/255} ${255/255} 1.0"/>
      </material>
    </visual>
  </link>
  <joint name="gps_joint" type="fixed">
    <parent link="base_link"/>
    <child link="gps_link"/>
    <origin xyz="-0.01 -.117 0.08" rpy="0 0 0"/>
  </joint>
  <gazebo reference="gps_link">
    <material>Gazebo/Blue</material>
  </gazebo>

</robot>
