<?xml version="1.0" ?>
<!-- =================================================================================== -->
<!-- |    This document was autogenerated by xacro from basic_rmp.urdf.xacro           | -->
<!-- |    EDITING THIS FILE BY HAND IS NOT RECOMMENDED                                 | -->
<!-- =================================================================================== -->
<robot name="rmp_401">
  <!-- <xacro:macro name="sphere_inertia" params="m r">
    <inertial>
      <mass value="${m}"/>
      <inertia ixx="${(2/5) * m * (r*r)}" ixy="0.0" ixz="0.0" iyy="${(2/5) * m * (r*r)}" iyz="0.0" izz="${(2/5) * m * (r*r)}"/>
    </inertial>
  </xacro:macro> -->
  <!-- ****************** ROBOT BASE FOOTPRINT ***************************  -->
  <!-- Define the center of the main robot chassis projected on the ground -->
  <link name="base_footprint"/>
  <!-- The base footprint of the robot is located underneath the chassis -->
  <joint name="base_joint" type="fixed">
    <parent link="base_footprint"/>
    <child link="base_link"/>
    <origin rpy="0 0 0" xyz="0.0 0.0 0.1575"/>
  </joint>
  <!-- ********************** ROBOT BASE *********************************  -->
  <link name="base_link">
    <visual>
      <origin rpy="1.5707963267949 0 0" xyz="-.355 -.3450 -.200"/>
      <geometry>
        <mesh filename="/home/luckierdodge/dev_ws/install/mcity_proxy/share/mcity_proxy/meshes/chassis.stl" scale="0.001 0.001 0.001"/>
      </geometry>
      <material name="Red">
        <color rgba="1.0 0.0 0.0 1.0"/>
      </material>
    </visual>
    <collision>
      <geometry>
        <box size="0.432 0.635 0.204"/>
      </geometry>
    </collision>
    <inertial>
      <origin rpy="1.5707963267948966 0 0" xyz="0 0 0"/>
      <mass value="20.0"/>
      <inertia ixx="0.7414016666666666" ixy="0.0" ixz="0.0" iyy="0.9830816666666666" iyz="0.0" izz="0.38039999999999996"/>
    </inertial>
  </link>
  <gazebo reference="base_link">
    <material>Gazebo/Red</material>
  </gazebo>
  <!-- ********************** STEER ARM  *********************************  -->
  <link name="front_steer_link">
    <visual>
      <origin rpy="1.5707963267949 0 0" xyz="-.355 -.5650 -.200"/>
      <geometry>
        <mesh filename="/home/luckierdodge/dev_ws/install/mcity_proxy/share/mcity_proxy/meshes/steering_arm.stl" scale="0.001 0.001 0.001"/>
      </geometry>
      <material name="Green">
        <color rgba="0.0 1.0 0.0 1.0"/>
      </material>
    </visual>
    <inertial>
      <origin rpy="0 0 0" xyz="0 0 0"/>
      <mass value="5.0"/>
      <inertia ixx="0.02004166666666667" ixy="0.0" ixz="0.0" iyy="0.09154166666666667" iyz="0.0" izz="0.10483333333333336"/>
    </inertial>
  </link>
  <joint name="steer_joint" type="revolute">
    <parent link="base_link"/>
    <child link="front_steer_link"/>
    <origin rpy="0 0 0" xyz="0 0.22 0"/>
    <limit effort="30" lower="-0.36" upper="0.36" velocity="5.0"/>
    <axis xyz="0 0 1"/>
  </joint>
  <gazebo reference="front_steer_link">
    <material>Gazebo/Green</material>
  </gazebo>
  <!-- *********************** FRONT WHEELS ******************************  -->
  <link name="frontwhl_r_link">
    <visual>
      <origin rpy="1.5707963267949 0 0" xyz="-0.575 -.5650 -.110"/>
      <geometry>
        <mesh filename="/home/luckierdodge/dev_ws/install/mcity_proxy/share/mcity_proxy/meshes/front_wheel.stl" scale="0.001 0.001 0.001"/>
      </geometry>
      <material name="White">
        <color rgba="1.0 1.0 1.0 1.0"/>
      </material>
    </visual>
    <collision>
      <origin rpy="0 1.5707963267948966 0" xyz=".048 0 0"/>
      <!-- <origin xyz="${-.355 - offset_multiplier * x_offset} -.5650 -.110" rpy="1.5707963267949 0 0"/> -->
      <geometry>
        <cylinder length="0.085" radius="0.1075"/>
      </geometry>
    </collision>
    <inertial>
      <origin rpy="0 1.5707963267948966 0" xyz=".048 0 0"/>
      <mass value="1"/>
      <inertia ixx="0.003491145833333333" ixy="0" ixz="0" iyy="0.003491145833333333" iyz="0" izz="0.005778124999999999"/>
    </inertial>
  </link>
  <joint name="frontwhl_r_joint" type="continuous">
    <parent link="front_steer_link"/>
    <child link="frontwhl_r_link"/>
    <!-- <origin xyz="${x_reflect*wheel_xoff} ${y_reflect*(base_width/2+wheel_ygap)} ${-wheel_zoff}" rpy="0 0 0"/> -->
    <origin rpy="0 0 0" xyz="0.22 0 -.09"/>
    <!-- <limit upper="3.1415" lower="-3.1415" effort="30" velocity="5.0"/> -->
    <axis xyz="1 0 0"/>
  </joint>
  <gazebo reference="frontwhl_r_link">
    <material>Gazebo/White</material>
  </gazebo>
  <link name="frontwhl_l_link">
    <visual>
      <origin rpy="1.5707963267949 0 0" xyz="-0.575 -.5650 -.110"/>
      <geometry>
        <mesh filename="/home/luckierdodge/dev_ws/install/mcity_proxy/share/mcity_proxy/meshes/front_wheel.stl" scale="0.001 0.001 0.001"/>
      </geometry>
      <material name="White">
        <color rgba="1.0 1.0 1.0 1.0"/>
      </material>
    </visual>
    <collision>
      <origin rpy="0 1.5707963267948966 0" xyz=".048 0 0"/>
      <!-- <origin xyz="${-.355 - offset_multiplier * x_offset} -.5650 -.110" rpy="1.5707963267949 0 0"/> -->
      <geometry>
        <cylinder length="0.085" radius="0.1075"/>
      </geometry>
    </collision>
    <inertial>
      <origin rpy="0 1.5707963267948966 0" xyz=".048 0 0"/>
      <mass value="1"/>
      <inertia ixx="0.003491145833333333" ixy="0" ixz="0" iyy="0.003491145833333333" iyz="0" izz="0.005778124999999999"/>
    </inertial>
  </link>
  <joint name="frontwhl_l_joint" type="continuous">
    <parent link="front_steer_link"/>
    <child link="frontwhl_l_link"/>
    <!-- <origin xyz="${x_reflect*wheel_xoff} ${y_reflect*(base_width/2+wheel_ygap)} ${-wheel_zoff}" rpy="0 0 0"/> -->
    <origin rpy="0 0 3.14159265359" xyz="-0.22 0 -.09"/>
    <!-- <limit upper="3.1415" lower="-3.1415" effort="30" velocity="5.0"/> -->
    <axis xyz="1 0 0"/>
  </joint>
  <gazebo reference="frontwhl_l_link">
    <material>Gazebo/White</material>
  </gazebo>
  <!-- ***********************  BACK WHEELS ******************************  -->
  <link name="backwhl_r_link">
    <visual>
      <origin rpy="1.5707963267949 0 0" xyz="-0.595 -.1100 -.110"/>
      <geometry>
        <mesh filename="/home/luckierdodge/dev_ws/install/mcity_proxy/share/mcity_proxy/meshes/back_wheel.stl" scale="0.001 0.001 0.001"/>
      </geometry>
      <material name="White">
        <color rgba="1.0 1.0 1.0 1.0"/>
      </material>
    </visual>
    <collision>
      <origin rpy="0 1.5707963267948966 0" xyz=".029 0 0"/>
      <geometry>
        <cylinder length="0.085" radius="0.1075"/>
      </geometry>
    </collision>
    <inertial>
      <origin rpy="0 1.5707963267948966 0" xyz=".029 0 0"/>
      <mass value="1"/>
      <inertia ixx="0.003491145833333333" ixy="0" ixz="0" iyy="0.003491145833333333" iyz="0" izz="0.005778124999999999"/>
    </inertial>
  </link>
  <joint name="backwhl_r_joint" type="continuous">
    <parent link="base_link"/>
    <child link="backwhl_r_link"/>
    <!-- <origin xyz="${x_reflect*wheel_xoff} ${y_reflect*(base_width/2+wheel_ygap)} ${-wheel_zoff}" rpy="0 0 0"/> -->
    <origin rpy="0 0 0" xyz="0.24 -.235 -.09"/>
    <!-- <limit upper="3.1415" lower="-3.1415" effort="30" velocity="5.0"/> -->
    <axis xyz="1 0 0"/>
  </joint>
  <gazebo reference="backwhl_r_link">
    <material>Gazebo/White</material>
  </gazebo>
  <link name="backwhl_l_link">
    <visual>
      <origin rpy="1.5707963267949 0 0" xyz="-0.595 -.1100 -.110"/>
      <geometry>
        <mesh filename="/home/luckierdodge/dev_ws/install/mcity_proxy/share/mcity_proxy/meshes/back_wheel.stl" scale="0.001 0.001 0.001"/>
      </geometry>
      <material name="White">
        <color rgba="1.0 1.0 1.0 1.0"/>
      </material>
    </visual>
    <collision>
      <origin rpy="0 1.5707963267948966 0" xyz=".029 0 0"/>
      <geometry>
        <cylinder length="0.085" radius="0.1075"/>
      </geometry>
    </collision>
    <inertial>
      <origin rpy="0 1.5707963267948966 0" xyz=".029 0 0"/>
      <mass value="1"/>
      <inertia ixx="0.003491145833333333" ixy="0" ixz="0" iyy="0.003491145833333333" iyz="0" izz="0.005778124999999999"/>
    </inertial>
  </link>
  <joint name="backwhl_l_joint" type="continuous">
    <parent link="base_link"/>
    <child link="backwhl_l_link"/>
    <!-- <origin xyz="${x_reflect*wheel_xoff} ${y_reflect*(base_width/2+wheel_ygap)} ${-wheel_zoff}" rpy="0 0 0"/> -->
    <origin rpy="0 0 3.14159265359" xyz="-0.24 -.235 -.09"/>
    <!-- <limit upper="3.1415" lower="-3.1415" effort="30" velocity="5.0"/> -->
    <axis xyz="1 0 0"/>
  </joint>
  <gazebo reference="backwhl_l_link">
    <material>Gazebo/White</material>
  </gazebo>
  <!-- *********************** GPS SETUP **********************************  -->
  <link name="gps_link">
    <visual>
      <geometry>
        <box size=".042 .05 .001"/>
      </geometry>
      <material name="Blue">
        <color rgba="0.0 0.0 1.0 1.0"/>
      </material>
    </visual>
  </link>
  <joint name="gps_joint" type="fixed">
    <parent link="base_link"/>
    <child link="gps_link"/>
    <origin rpy="0 0 0" xyz="-0.01 -.117 0.08"/>
  </joint>
  <gazebo reference="gps_link">
    <material>Gazebo/Blue</material>
  </gazebo>
  <inertial>
    <origin rpy="0 0 0" xyz="0 0 0"/>
    <mass value="0.1"/>
    <inertia ixx="2.084166666666667e-05" ixy="0.0" ixz="0.0" iyy="3.5533333333333334e-05" iyz="0.0" izz="1.4708333333333335e-05"/>
  </inertial>
</robot>
